<?xml version="1.0"?>


<robot name="hermes" xmlns:xacro="http://www.ros.org/wiki/xacro">
<xacro:property name="M_PI" value="3.1415926535897931" />
<xacro:property name="M_PI2" value="-3.1415926535897931" />
 <material name="blue">
    <color rgba="0 0 0.8 1"/>
  </material>
  <material name="black">
    <color rgba="0 0 0 1"/>
  </material>




<link name="base_link">
    <inertial>
      <mass value="1.0" />
      <inertia ixx="0.015" iyy="0.0375" izz="0.0375" ixy="0" ixz="0" iyz="0" />
    </inertial>
    <visual>
      <geometry>
        <box size="1.16195 0.651 0.77596" />
      </geometry>
      <material name="blue">
        <color rgba="0.75 0.75 0.75 1" />
      </material>
    </visual>
    <collision>
      <geometry>
        <box size="0.6 0.3 0.3" />
      </geometry>
    </collision>
  </link>
<link name="back_caster">
    <inertial>
      <mass value="0.1" />
      <inertia ixx="0.00083" iyy="0.00083" izz="0.000167" ixy="0" ixz="0" iyz="0" />
    </inertial>
    <visual>
      <geometry>
        <box size="0.1 0.1 0.77596" />
      </geometry>
      <material name="black" />
    </visual>
    <collision>
      <geometry>
        <box size="0.1 0.1 0.77596" />
      </geometry>
    </collision>
  </link>
  <joint name="back_caster_joint" type="continuous">
    <axis xyz="0 0 1" />
    <parent link="base_link" />
    <child link="back_caster" />
    <origin rpy="0 0 0" xyz="-0.491695 0 0" />
  </joint>
  <link name="back_wheel">
    <inertial>
      <mass value="0.1" />
      <inertia ixx="5.1458e-5" iyy="5.1458e-5" izz="6.125e-5" ixy="0" ixz="0" iyz="0" />
    </inertial>
    <visual>
      <geometry>
        <cylinder length="0.05" radius="0.1" />
      </geometry>
      <material name="black" />
    </visual>
    <collision>
      <geometry>
        <cylinder length="0.05" radius="0.1" />
      </geometry>
    </collision>

  </link>
  <joint name="back_wheel_joint" type="continuous">
    <axis xyz="0 0 1" />
    <parent link="back_caster" />
    <child link="back_wheel" />
    <origin rpy="-1.5708 0 0" xyz="0.05 0 -.38798" />
  </joint>
  <link name="front_caster">
    <inertial>
      <mass value="0.1" />
      <inertia ixx="0.00083" iyy="0.00083" izz="0.000167" ixy="0" ixz="0" iyz="0" />
    </inertial>
    <visual>
      <geometry>
        <box size="0.1 0.1 0.77596" />
      </geometry>
      <material name="blue" />
    </visual>
    <collision>
      <geometry>
        <box size="0.1 0.1 0.77596" />
      </geometry>
    </collision>
  </link>
  <joint name="front_caster_joint" type="continuous">
    <axis xyz="0 0 1" />
    <parent link="base_link" />
    <child link="front_caster" />
    <origin rpy="0 0 0" xyz="0.491695 0 0" />
  </joint>
  <link name="front_wheel">
    <inertial>
      <mass value="0.1" />
      <inertia ixx="5.1458e-5" iyy="5.1458e-5" izz="6.125e-5" ixy="0" ixz="0" iyz="0" />
    </inertial>
    <visual>
      <geometry>
        <cylinder length="0.05" radius="0.1" />
      </geometry>
      <material name="black" />
    </visual>
    <collision>
      <geometry>
        <cylinder length="0.05" radius="0.1" />
      </geometry>
    </collision>

  </link>
  <joint name="front_wheel_joint" type="continuous">
    <axis xyz="0 0 1" />
    <parent link="front_caster" />
    <child link="front_wheel" />
    <origin rpy="-1.5708 0 0" xyz="0.05 0 -.38798" />
  </joint>
  <link name="right_wheel">
    <inertial>
      <mass value="0.1" />
      <inertia ixx="5.1458e-5" iyy="5.1458e-5" izz="6.125e-5" ixy="0" ixz="0" iyz="0" />
    </inertial>
    <visual>
      <geometry>
        <cylinder length="0.05" radius="0.1" />
      </geometry>
      <material name="black">
        <color rgba="0 0 0 1" />
      </material>
    </visual>
    <collision>
      <geometry>
        <cylinder length="0.05" radius="0.1" />
      </geometry>
    </collision>
  </link>
  <joint name="right_wheel_joint" type="continuous">
    <axis xyz="0 0 1" />
    <parent link="base_link" />
    <child link="right_wheel" />
    <origin rpy="-1.5708 0 0" xyz="0.159795 -.3005 -.38798" />
  </joint>
  <link name="left_wheel">
    <inertial>
      <mass value="0.1" />
      <inertia ixx="5.1458e-5" iyy="5.1458e-5" izz="6.125e-5" ixy="0" ixz="0" iyz="0" />
    </inertial>
    <visual>
      <geometry>
        <cylinder length="0.05" radius="0.1" />
      </geometry>
      <material name="black" />
    </visual>
    <collision>
      <geometry>
        <cylinder length="0.05" radius="0.1" />
      </geometry>
    </collision>
  </link>
  <joint name="left_wheel_joint" type="continuous">
    <axis xyz="0 0 1" />
    <parent link="base_link" />
    <child link="left_wheel" />
    <origin rpy="-1.5708 0 0" xyz="0.159795 0.3005 -.38978" />
  </joint>
  <link name="lidar_link">
    <collision>
      <origin xyz="0 0 0" rpy="0 0 0" />
      <geometry>
        <box size="0.1 0.1 0.1" />
      </geometry>
    </collision>
    <visual>
      <origin xyz="0 0 0" rpy="0 0 0" />
      <geometry>
        <box size="0.1 0.1 0.1" />
      </geometry>
    </visual>
    <inertial>
      <mass value="1e-5" />
      <origin xyz="0 0 0" rpy="0 0 0" />
      <inertia ixx="1e-6" ixy="0" ixz="0" iyy="1e-6" iyz="0" izz="1e-6" />
    </inertial>
  </link>
  <joint name="lidar_joint" type="fixed">
    <origin xyz="0.630975 0 -0.1807467" rpy="0 0 0" />
    <parent link="base_link" />
    <child link="lidar_link" />
  </joint>
 

<gazebo reference="lidar_link">
      
<sensor type="ray" name="lidar_link">
          <pose>0 0 0 0 0 0</pose>
          <visualize>false</visualize>
          <update_rate>10</update_rate>
          <ray>
            <scan>
              <horizontal>
                <samples>1875</samples>
                <resolution>1</resolution>
                <min_angle>-3</min_angle>
                <max_angle>3</max_angle>
              </horizontal>
              <vertical>
                <samples>16</samples>
                <resolution>1</resolution>
                <min_angle>-0.25</min_angle>
                <max_angle>0.25</max_angle>
              </vertical>
            </scan>
            <range>
              <min>0.3</min>
              <max>131.0</max>
              <resolution>0.001</resolution>
            </range>
            <noise>
              <type>gaussian</type>
              <mean>0.0</mean>
              <stddev>0.0</stddev>
            </noise>
          </ray>
          <plugin name="gazebo_ros_laser_controller" filename="libgazebo_ros_velodyne_laser.so">
            <topicName>/velodyne</topicName>
            <frameName>lidar_link</frameName>
            <min_range>0.9</min_range>
            <max_range>130.0</max_range>
            <gaussianNoise>0.008</gaussianNoise>
          </plugin>
        </sensor>
    </gazebo>

</robot>